Workbook

Sheet 공헌이익
A1: 거래처 | B1: 출고액 | C1: 반품액 | D1: 출고원가 | E1: 재판매가능원가 | F1: 반품부수 | G1: 출고부수 | H1: 재판매불가부수 | I1: 공헌이익(수식) | J1: 공헌이익(대시보드) | K1: 차이 | L1: 손익분기(수식) | M1: 손익분기(대시보드) | N1: 차이 | O1: 물류비
A2: 한솔북센 | B2: =SUMIFS(출고!F:F,출고!B:B,A2) -> 11421191000 | C2: =SUMIFS(반품!G:G,반품!B:B,A2) -> 4.2461149e+09 | D2: =SUMIFS(출고!H:H,출고!B:B,A2) -> 5959374400 | E2: =SUMIFS(반품!I:I,반품!B:B,A2) -> 1534822210 | F2: =SUMIFS(반품!D:D,반품!B:B,A2) -> 381708 | G2: =SUMIFS(출고!D:D,출고!B:B,A2) -> 1014080 | H2: =SUMIFS(반품!D:D,반품!B:B,A2,반품!E:E,"개정판교체")+SUMIFS(반품!D:D,반품!B:B,A2,반품!E:E,"파본") -> 112587 | I2: =B2-C2-(D2-E2)-F2*$O$2 -> 2.2161327e+09 | J2: 2.2161327e+09 | K2: =I2-J2 -> 0 | L2: =(B2/G2-D2/G2)/(B2/G2-D2/G2+$O$2+H2/F2*D2/G2) -> 0.63220732 | M2: 0.63220732 | N2: =L2-M2 -> 0 | O2: 1400
A3: 대명서적유통 | B3: =SUMIFS(출고!F:F,출고!B:B,A3) -> 10389744900 | C3: =SUMIFS(반품!G:G,반품!B:B,A3) -> 1.3611149e+09 | D3: =SUMIFS(출고!H:H,출고!B:B,A3) -> 5389073600 | E3: =SUMIFS(반품!I:I,반품!B:B,A3) -> 349608690 | F3: =SUMIFS(반품!D:D,반품!B:B,A3) -> 124449 | G3: =SUMIFS(출고!D:D,출고!B:B,A3) -> 931140 | H3: =SUMIFS(반품!D:D,반품!B:B,A3,반품!E:E,"개정판교체")+SUMIFS(반품!D:D,반품!B:B,A3,반품!E:E,"파본") -> 60681 | I3: =B3-C3-(D3-E3)-F3*$O$2 -> 3.8149365e+09 | J3: 3.8149365e+09 | K3: =I3-J3 -> 0 | L3: =(B3/G3-D3/G3)/(B3/G3-D3/G3+$O$2+H3/F3*D3/G3) -> 0.55986238 | M3: 0.55986238 | N3: =L3-M3 -> 0
A4: 북웨이브몰 | B4: =SUMIFS(출고!F:F,출고!B:B,A4) -> 8746881600 | C4: =SUMIFS(반품!G:G,반품!B:B,A4) -> 7.3141311e+08 | D4: =SUMIFS(출고!H:H,출고!B:B,A4) -> 4171004900 | E4: =SUMIFS(반품!I:I,반품!B:B,A4) -> 176243150 | F4: =SUMIFS(반품!D:D,반품!B:B,A4) -> 60010 | G4: =SUMIFS(출고!D:D,출고!B:B,A4) -> 711550 | H4: =SUMIFS(반품!D:D,반품!B:B,A4,반품!E:E,"개정판교체")+SUMIFS(반품!D:D,반품!B:B,A4,반품!E:E,"파본") -> 29547 | I4: =B4-C4-(D4-E4)-F4*$O$2 -> 3.9366927e+09 | J4: 3.9366927e+09 | K4: =I4-J4 -> 0 | L4: =(B4/G4-D4/G4)/(B4/G4-D4/G4+$O$2+H4/F4*D4/G4) -> 0.60005865 | M4: 0.60005865 | N4: =L4-M4 -> 0
A5: 남강교재총판 | B5: =SUMIFS(출고!F:F,출고!B:B,A5) -> 6692673900 | C5: =SUMIFS(반품!G:G,반품!B:B,A5) -> 9.2960288e+08 | D5: =SUMIFS(출고!H:H,출고!B:B,A5) -> 3510146100 | E5: =SUMIFS(반품!I:I,반품!B:B,A5) -> 259410200 | F5: =SUMIFS(반품!D:D,반품!B:B,A5) -> 84253 | G5: =SUMIFS(출고!D:D,출고!B:B,A5) -> 592670 | H5: =SUMIFS(반품!D:D,반품!B:B,A5,반품!E:E,"개정판교체")+SUMIFS(반품!D:D,반품!B:B,A5,반품!E:E,"파본") -> 38504 | I5: =B5-C5-(D5-E5)-F5*$O$2 -> 2.3943809e+09 | J5: 2.3943809e+09 | K5: =I5-J5 -> 0 | L5: =(B5/G5-D5/G5)/(B5/G5-D5/G5+$O$2+H5/F5*D5/G5) -> 0.56664721 | M5: 0.56664721 | N5: =L5-M5 -> 0
A6: 페이지온몰 | B6: =SUMIFS(출고!F:F,출고!B:B,A6) -> 6153188800 | C6: =SUMIFS(반품!G:G,반품!B:B,A6) -> 3.6525314e+08 | D6: =SUMIFS(출고!H:H,출고!B:B,A6) -> 2970551300 | E6: =SUMIFS(반품!I:I,반품!B:B,A6) -> 141891700 | F6: =SUMIFS(반품!D:D,반품!B:B,A6) -> 28865 | G6: =SUMIFS(출고!D:D,출고!B:B,A6) -> 487920 | H6: =SUMIFS(반품!D:D,반품!B:B,A6,반품!E:E,"개정판교체")+SUMIFS(반품!D:D,반품!B:B,A6,반품!E:E,"파본") -> 5390 | I6: =B6-C6-(D6-E6)-F6*$O$2 -> 2.9188651e+09 | J6: 2.9188651e+09 | K6: =I6-J6 -> 0 | L6: =(B6/G6-D6/G6)/(B6/G6-D6/G6+$O$2+H6/F6*D6/G6) -> 0.71998523 | M6: 0.71998523 | N6: =L6-M6 -> 0
A7: 세림북유통 | B7: =SUMIFS(출고!F:F,출고!B:B,A7) -> 4702313300 | C7: =SUMIFS(반품!G:G,반품!B:B,A7) -> 4.4590657e+08 | D7: =SUMIFS(출고!H:H,출고!B:B,A7) -> 2453604000 | E7: =SUMIFS(반품!I:I,반품!B:B,A7) -> 143358940 | F7: =SUMIFS(반품!D:D,반품!B:B,A7) -> 38823 | G7: =SUMIFS(출고!D:D,출고!B:B,A7) -> 414570 | H7: =SUMIFS(반품!D:D,반품!B:B,A7,반품!E:E,"개정판교체")+SUMIFS(반품!D:D,반품!B:B,A7,반품!E:E,"파본") -> 14262 | I7: =B7-C7-(D7-E7)-F7*$O$2 -> 1.8918095e+09 | J7: 1.8918095e+09 | K7: =I7-J7 -> 0 | L7: =(B7/G7-D7/G7)/(B7/G7-D7/G7+$O$2+H7/F7*D7/G7) -> 0.60279644 | M7: 0.60279644 | N7: =L7-M7 -> 0
A8: 하루책방닷컴 | B8: =SUMIFS(출고!F:F,출고!B:B,A8) -> 3582902400 | C8: =SUMIFS(반품!G:G,반품!B:B,A8) -> 2.216486e+08 | D8: =SUMIFS(출고!H:H,출고!B:B,A8) -> 1713506100 | E8: =SUMIFS(반품!I:I,반품!B:B,A8) -> 79805640 | F8: =SUMIFS(반품!D:D,반품!B:B,A8) -> 17884 | G8: =SUMIFS(출고!D:D,출고!B:B,A8) -> 289980 | H8: =SUMIFS(반품!D:D,반품!B:B,A8,반품!E:E,"개정판교체")+SUMIFS(반품!D:D,반품!B:B,A8,반품!E:E,"파본") -> 3926 | I8: =B8-C8-(D8-E8)-F8*$O$2 -> 1.7025157e+09 | J8: 1.7025157e+09 | K8: =I8-J8 -> 0 | L8: =(B8/G8-D8/G8)/(B8/G8-D8/G8+$O$2+H8/F8*D8/G8) -> 0.70502627 | M8: 0.70502627 | N8: =L8-M8 -> 0
A9: 책마루서점 | B9: =SUMIFS(출고!F:F,출고!B:B,A9) -> 3172452200 | C9: =SUMIFS(반품!G:G,반품!B:B,A9) -> 3.5242357e+08 | D9: =SUMIFS(출고!H:H,출고!B:B,A9) -> 1518714800 | E9: =SUMIFS(반품!I:I,반품!B:B,A9) -> 149274640 | F9: =SUMIFS(반품!D:D,반품!B:B,A9) -> 30153 | G9: =SUMIFS(출고!D:D,출고!B:B,A9) -> 275820 | H9: =SUMIFS(반품!D:D,반품!B:B,A9,반품!E:E,"개정판교체")+SUMIFS(반품!D:D,반품!B:B,A9,반품!E:E,"파본") -> 2887 | I9: =B9-C9-(D9-E9)-F9*$O$2 -> 1.4083743e+09 | J9: 1.4083743e+09 | K9: =I9-J9 -> 0 | L9: =(B9/G9-D9/G9)/(B9/G9-D9/G9+$O$2+H9/F9*D9/G9) -> 0.75675712 | M9: 0.75675712 | N9: =L9-M9 -> 0
A10: 글벗문고 | B10: =SUMIFS(출고!F:F,출고!B:B,A10) -> 2883635300 | C10: =SUMIFS(반품!G:G,반품!B:B,A10) -> 2.9341963e+08 | D10: =SUMIFS(출고!H:H,출고!B:B,A10) -> 1390851400 | E10: =SUMIFS(반품!I:I,반품!B:B,A10) -> 110279680 | F10: =SUMIFS(반품!D:D,반품!B:B,A10) -> 23287 | G10: =SUMIFS(출고!D:D,출고!B:B,A10) -> 230020 | H10: =SUMIFS(반품!D:D,반품!B:B,A10,반품!E:E,"개정판교체")+SUMIFS(반품!D:D,반품!B:B,A10,반품!E:E,"파본") -> 4800 | I10: =B10-C10-(D10-E10)-F10*$O$2 -> 1.2770422e+09 | J10: 1.2770422e+09 | K10: =I10-J10 -> 0 | L10: =(B10/G10-D10/G10)/(B10/G10-D10/G10+$O$2+H10/F10*D10/G10) -> 0.71034237 | M10: 0.71034237 | N10: =L10-M10 -> 0
A11: 한빛서림 | B11: =SUMIFS(출고!F:F,출고!B:B,A11) -> 2661978300 | C11: =SUMIFS(반품!G:G,반품!B:B,A11) -> 3.0842068e+08 | D11: =SUMIFS(출고!H:H,출고!B:B,A11) -> 1286984700 | E11: =SUMIFS(반품!I:I,반품!B:B,A11) -> 124421030 | F11: =SUMIFS(반품!D:D,반품!B:B,A11) -> 23744 | G11: =SUMIFS(출고!D:D,출고!B:B,A11) -> 203690 | H11: =SUMIFS(반품!D:D,반품!B:B,A11,반품!E:E,"개정판교체")+SUMIFS(반품!D:D,반품!B:B,A11,반품!E:E,"파본") -> 3976 | I11: =B11-C11-(D11-E11)-F11*$O$2 -> 1.1577524e+09 | J11: 1.1577524e+09 | K11: =I11-J11 -> 0 | L11: =(B11/G11-D11/G11)/(B11/G11-D11/G11+$O$2+H11/F11*D11/G11) -> 0.73306843 | M11: 0.73306843 | N11: =L11-M11 -> 0
A12: 청람서점 | B12: =SUMIFS(출고!F:F,출고!B:B,A12) -> 1998191500 | C12: =SUMIFS(반품!G:G,반품!B:B,A12) -> 2.1047553e+08 | D12: =SUMIFS(출고!H:H,출고!B:B,A12) -> 955073900 | E12: =SUMIFS(반품!I:I,반품!B:B,A12) -> 84982660 | F12: =SUMIFS(반품!D:D,반품!B:B,A12) -> 17226 | G12: =SUMIFS(출고!D:D,출고!B:B,A12) -> 163220 | H12: =SUMIFS(반품!D:D,반품!B:B,A12,반품!E:E,"개정판교체")+SUMIFS(반품!D:D,반품!B:B,A12,반품!E:E,"파본") -> 2606 | I12: =B12-C12-(D12-E12)-F12*$O$2 -> 8.9350833e+08 | J12: 8.9350833e+08 | K12: =I12-J12 -> 0 | L12: =(B12/G12-D12/G12)/(B12/G12-D12/G12+$O$2+H12/F12*D12/G12) -> 0.73660671 | M12: 0.73660671 | N12: =L12-M12 -> 0
A13: 다온북스 | B13: =SUMIFS(출고!F:F,출고!B:B,A13) -> 1924083300 | C13: =SUMIFS(반품!G:G,반품!B:B,A13) -> 1.8800068e+08 | D13: =SUMIFS(출고!H:H,출고!B:B,A13) -> 916663600 | E13: =SUMIFS(반품!I:I,반품!B:B,A13) -> 77921210 | F13: =SUMIFS(반품!D:D,반품!B:B,A13) -> 16857 | G13: =SUMIFS(출고!D:D,출고!B:B,A13) -> 165570 | H13: =SUMIFS(반품!D:D,반품!B:B,A13,반품!E:E,"개정판교체")+SUMIFS(반품!D:D,반품!B:B,A13,반품!E:E,"파본") -> 1607 | I13: =B13-C13-(D13-E13)-F13*$O$2 -> 8.7374043e+08 | J13: 8.7374043e+08 | K13: =I13-J13 -> 0 | L13: =(B13/G13-D13/G13)/(B13/G13-D13/G13+$O$2+H13/F13*D13/G13) -> 0.7593972 | M13: 0.7593972 | N13: =L13-M13 -> 0

Sheet 출고
A1: 월 | B1: 거래처명 | C1: 시리즈명 | D1: 출고부수 | E1: 공급단가 | F1: 출고액 | G1: 제작원가 | H1: 출고원가
A2: 2024-01 | B2: 한솔북센 | C2: 개념단단 사회 중1 | D2: 8420 | E2: 10990 | F2: =D2*E2 -> 92535800 | G2: =INDEX(마스터!$E:$E,MATCH(C2,마스터!$A:$A,0)) -> 5790 | H2: =D2*G2 -> 48751800
A3: 2024-01 | B3: 한솔북센 | C3: 기출정복 수학 고1 | D3: 9220 | E3: 12280 | F3: =D3*E3 -> 113221600 | G3: =INDEX(마스터!$E:$E,MATCH(C3,마스터!$A:$A,0)) -> 6790 | H3: =D3*G3 -> 62603800
A4: 2024-01 | B4: 한솔북센 | C4: 실전만점 국어 고1 | D4: 8960 | E4: 11960 | F4: =D4*E4 -> 107161600 | G4: =INDEX(마스터!$E:$E,MATCH(C4,마스터!$A:$A,0)) -> 6630 | H4: =D4*G4 -> 59404800
A5: 2024-01 | B5: 한솔북센 | C5: 첫걸음 수학 초6 | D5: 6730 | E5: 9700 | F5: =D5*E5 -> 65281000 | G5: =INDEX(마스터!$E:$E,MATCH(C5,마스터!$A:$A,0)) -> 4920 | H5: =D5*G5 -> 33111600
A6: 2024-01 | B6: 한솔북센 | C6: 첫걸음 영어 초5 | D6: 6740 | E6: 9370 | F6: =D6*E6 -> 63153800 | G6: =INDEX(마스터!$E:$E,MATCH(C6,마스터!$A:$A,0)) -> 4540 | H6: =D6*G6 -> 30599600
A7: 2024-01 | B7: 대명서적유통 | C7: 개념단단 국어 중1 | D7: 8350 | E7: 9730 | F7: =D7*E7 -> 81245500 | G7: =INDEX(마스터!$E:$E,MATCH(C7,마스터!$A:$A,0)) -> 4900 | H7: =D7*G7 -> 40915000
A8: 2024-01 | B8: 대명서적유통 | C8: 개념단단 수학 중2 | D8: 8310 | E8: 11350 | F8: =D8*E8 -> 94318500 | G8: =INDEX(마스터!$E:$E,MATCH(C8,마스터!$A:$A,0)) -> 5670 | H8: =D8*G8 -> 47117700
A9: 2024-01 | B9: 대명서적유통 | C9: 완성노트 국어 중1 | D9: 8220 | E9: 11030 | F9: =D9*E9 -> 90666600 | G9: =INDEX(마스터!$E:$E,MATCH(C9,마스터!$A:$A,0)) -> 5660 | H9: =D9*G9 -> 46525200
A10: 2024-01 | B10: 대명서적유통 | C10: 첫걸음 영어 초5 | D10: 6950 | E10: 9410 | F10: =D10*E10 -> 65399500 | G10: =INDEX(마스터!$E:$E,MATCH(C10,마스터!$A:$A,0)) -> 4540 | H10: =D10*G10 -> 31553000
A11: 2024-01 | B11: 대명서적유통 | C11: 한권끝 영어 초5 | D11: 7060 | E11: 9080 | F11: =D11*E11 -> 64104800 | G11: =INDEX(마스터!$E:$E,MATCH(C11,마스터!$A:$A,0)) -> 4740 | H11: =D11*G11 -> 33464400
A12: 2024-01 | B12: 북웨이브몰 | C12: 개념단단 영어 중1 | D12: 10280 | E12: 12230 | F12: =D12*E12 -> 125724400 | G12: =INDEX(마스터!$E:$E,MATCH(C12,마스터!$A:$A,0)) -> 5480 | H12: =D12*G12 -> 56334400
A13: 2024-01 | B13: 북웨이브몰 | C13: 실전만점 수학 고2 | D13: 9410 | E13: 13670 | F13: =D13*E13 -> 128634700 | G13: =INDEX(마스터!$E:$E,MATCH(C13,마스터!$A:$A,0)) -> 6730 | H13: =D13*G13 -> 63329300
... A1167: 2025-12 | B1167: 청람서점 | C1167: 한권끝 수학 초6 | D1167: 3810 | E1167: 9110 | F1167: =D1167*E1167 -> 34709100 | G1167: =INDEX(마스터!$E:$E,MATCH(C1167,마스터!$A:$A,0)) -> 4170 | H1167: =D1167*G1167 -> 15887700

Sheet 반품
A1: 월 | B1: 거래처명 | C1: 시리즈명 | D1: 반품부수 | E1: 반품사유 | F1: 단가 | G1: 반품액 | H1: 제작원가 | I1: 재판매가능원가
A2: 2024-03 | B2: 한솔북센 | C2: 기출정복 수학 고1 | D2: 5791 | E2: 기간만료반품 | F2: =SUMIFS(출고!$F$2:$F$1167,출고!$B$2:$B$1167,B2,출고!$C$2:$C$1167,C2)/SUMIFS(출고!$D$2:$D$1167,출고!$B$2:$B$1167,B2,출고!$C$2:$C$1167,C2) -> 12269.491 | G2: =D2*F2 -> 71052622 | H2: =INDEX(마스터!$E:$E,MATCH(C2,마스터!$A:$A,0)) -> 6790 | I2: =IF(OR(E2="개정판교체",E2="파본"),0,D2*H2) -> 39320890
A3: 2024-03 | B3: 대명서적유통 | C3: 개념단단 국어 중1 | D3: 1297 | E3: 재고조정 | F3: =SUMIFS(출고!$F$2:$F$1167,출고!$B$2:$B$1167,B3,출고!$C$2:$C$1167,C3)/SUMIFS(출고!$D$2:$D$1167,출고!$B$2:$B$1167,B3,출고!$C$2:$C$1167,C3) -> 9748.3614 | G3: =D3*F3 -> 12643625 | H3: =INDEX(마스터!$E:$E,MATCH(C3,마스터!$A:$A,0)) -> 4900 | I3: =IF(OR(E3="개정판교체",E3="파본"),0,D3*H3) -> 6355300
A4: 2024-03 | B4: 북웨이브몰 | C4: 첫걸음 수학 중2 | D4: 249 | E4: 재고조정 | F4: =SUMIFS(출고!$F$2:$F$1167,출고!$B$2:$B$1167,B4,출고!$C$2:$C$1167,C4)/SUMIFS(출고!$D$2:$D$1167,출고!$B$2:$B$1167,B4,출고!$C$2:$C$1167,C4) -> 12069.645 | G4: =D4*F4 -> 3005341.6 | H4: =INDEX(마스터!$E:$E,MATCH(C4,마스터!$A:$A,0)) -> 5500 | I4: =IF(OR(E4="개정판교체",E4="파본"),0,D4*H4) -> 1369500
A5: 2024-03 | B5: 남강교재총판 | C5: 기출정복 영어 고2 | D5: 1218 | E5: 재고조정 | F5: =SUMIFS(출고!$F$2:$F$1167,출고!$B$2:$B$1167,B5,출고!$C$2:$C$1167,C5)/SUMIFS(출고!$D$2:$D$1167,출고!$B$2:$B$1167,B5,출고!$C$2:$C$1167,C5) -> 13223.033 | G5: =D5*F5 -> 16105654 | H5: =INDEX(마스터!$E:$E,MATCH(C5,마스터!$A:$A,0)) -> 6910 | I5: =IF(OR(E5="개정판교체",E5="파본"),0,D5*H5) -> 8416380
A6: 2024-03 | B6: 세림북유통 | C6: 첫걸음 영어 중1 | D6: 362 | E6: 기간만료반품 | F6: =SUMIFS(출고!$F$2:$F$1167,출고!$B$2:$B$1167,B6,출고!$C$2:$C$1167,C6)/SUMIFS(출고!$D$2:$D$1167,출고!$B$2:$B$1167,B6,출고!$C$2:$C$1167,C6) -> 10384.083 | G6: =D6*F6 -> 3759038.2 | H6: =INDEX(마스터!$E:$E,MATCH(C6,마스터!$A:$A,0)) -> 5110 | I6: =IF(OR(E6="개정판교체",E6="파본"),0,D6*H6) -> 1849820
A7: 2024-03 | B7: 하루책방닷컴 | C7: 실전만점 영어 고1 | D7: 362 | E7: 기간만료반품 | F7: =SUMIFS(출고!$F$2:$F$1167,출고!$B$2:$B$1167,B7,출고!$C$2:$C$1167,C7)/SUMIFS(출고!$D$2:$D$1167,출고!$B$2:$B$1167,B7,출고!$C$2:$C$1167,C7) -> 13083.909 | G7: =D7*F7 -> 4736375.1 | H7: =INDEX(마스터!$E:$E,MATCH(C7,마스터!$A:$A,0)) -> 6040 | I7: =IF(OR(E7="개정판교체",E7="파본"),0,D7*H7) -> 2186480
A8: 2024-03 | B8: 하루책방닷컴 | C8: 실전만점 영어 고1 | D8: 195 | E8: 파본 | F8: =SUMIFS(출고!$F$2:$F$1167,출고!$B$2:$B$1167,B8,출고!$C$2:$C$1167,C8)/SUMIFS(출고!$D$2:$D$1167,출고!$B$2:$B$1167,B8,출고!$C$2:$C$1167,C8) -> 13083.909 | G8: =D8*F8 -> 2551362.3 | H8: =INDEX(마스터!$E:$E,MATCH(C8,마스터!$A:$A,0)) -> 6040 | I8: =IF(OR(E8="개정판교체",E8="파본"),0,D8*H8) -> 0
A9: 2024-04 | B9: 한솔북센 | C9: 첫걸음 수학 초6 | D9: 2815 | E9: 기간만료반품 | F9: =SUMIFS(출고!$F$2:$F$1167,출고!$B$2:$B$1167,B9,출고!$C$2:$C$1167,C9)/SUMIFS(출고!$D$2:$D$1167,출고!$B$2:$B$1167,B9,출고!$C$2:$C$1167,C9) -> 9672.9711 | G9: =D9*F9 -> 27229414 | H9: =INDEX(마스터!$E:$E,MATCH(C9,마스터!$A:$A,0)) -> 4920 | I9: =IF(OR(E9="개정판교체",E9="파본"),0,D9*H9) -> 13849800
A10: 2024-04 | B10: 한솔북센 | C10: 첫걸음 영어 초5 | D10: 2494 | E10: 기간만료반품 | F10: =SUMIFS(출고!$F$2:$F$1167,출고!$B$2:$B$1167,B10,출고!$C$2:$C$1167,C10)/SUMIFS(출고!$D$2:$D$1167,출고!$B$2:$B$1167,B10,출고!$C$2:$C$1167,C10) -> 9351.3096 | G10: =D10*F10 -> 23322166 | H10: =INDEX(마스터!$E:$E,MATCH(C10,마스터!$A:$A,0)) -> 4540 | I10: =IF(OR(E10="개정판교체",E10="파본"),0,D10*H10) -> 11322760
A11: 2024-04 | B11: 한솔북센 | C11: 한권끝 수학 초6 | D11: 4013 | E11: 재고조정 | F11: =SUMIFS(출고!$F$2:$F$1167,출고!$B$2:$B$1167,B11,출고!$C$2:$C$1167,C11)/SUMIFS(출고!$D$2:$D$1167,출고!$B$2:$B$1167,B11,출고!$C$2:$C$1167,C11) -> 8382.2726 | G11: =D11*F11 -> 33638060 | H11: =INDEX(마스터!$E:$E,MATCH(C11,마스터!$A:$A,0)) -> 4170 | I11: =IF(OR(E11="개정판교체",E11="파본"),0,D11*H11) -> 16734210
A12: 2024-04 | B12: 대명서적유통 | C12: 한권끝 영어 초5 | D12: 1554 | E12: 기간만료반품 | F12: =SUMIFS(출고!$F$2:$F$1167,출고!$B$2:$B$1167,B12,출고!$C$2:$C$1167,C12)/SUMIFS(출고!$D$2:$D$1167,출고!$B$2:$B$1167,B12,출고!$C$2:$C$1167,C12) -> 9097.316 | G12: =D12*F12 -> 14137229 | H12: =INDEX(마스터!$E:$E,MATCH(C12,마스터!$A:$A,0)) -> 4740 | I12: =IF(OR(E12="개정판교체",E12="파본"),0,D12*H12) -> 7365960
A13: 2024-04 | B13: 북웨이브몰 | C13: 개념단단 영어 중1 | D13: 884 | E13: 기간만료반품 | F13: =SUMIFS(출고!$F$2:$F$1167,출고!$B$2:$B$1167,B13,출고!$C$2:$C$1167,C13)/SUMIFS(출고!$D$2:$D$1167,출고!$B$2:$B$1167,B13,출고!$C$2:$C$1167,C13) -> 12005.609 | G13: =D13*F13 -> 10612958 | H13: =INDEX(마스터!$E:$E,MATCH(C13,마스터!$A:$A,0)) -> 5480 | I13: =IF(OR(E13="개정판교체",E13="파본"),0,D13*H13) -> 4844320
... A642: 2025-12 | B642: 청람서점 | C642: 실전만점 수학 고2 | D642: 339 | E642: 파본 | F642: =SUMIFS(출고!$F$2:$F$1167,출고!$B$2:$B$1167,B642,출고!$C$2:$C$1167,C642)/SUMIFS(출고!$D$2:$D$1167,출고!$B$2:$B$1167,B642,출고!$C$2:$C$1167,C642) -> 13332.489 | G642: =D642*F642 -> 4519713.7 | H642: =INDEX(마스터!$E:$E,MATCH(C642,마스터!$A:$A,0)) -> 6730 | I642: =IF(OR(E642="개정판교체",E642="파본"),0,D642*H642) -> 0

Sheet 마스터
A1: 시리즈명 | B1: 과목 | C1: 학년 | D1: 정가_원 | E1: 제작원가_원부 | F1: 개정판출간월
A2: 개념단단 국어 중1 | B2: 국어 | C2: 중1 | D2: 15000 | E2: 4900
A3: 개념단단 국어 중2 | B3: 국어 | C3: 중2 | D3: 15500 | E3: 5430
A4: 개념단단 국어 중3 | B4: 국어 | C4: 중3 | D4: 18500 | E4: 6110 | F4: 2025-09
A5: 개념단단 영어 중1 | B5: 영어 | C5: 중1 | D5: 17000 | E5: 5480 | F5: 2025-03
A6: 개념단단 영어 중2 | B6: 영어 | C6: 중2 | D6: 17000 | E6: 5380
A7: 개념단단 영어 중3 | B7: 영어 | C7: 중3 | D7: 16500 | E7: 5290
A8: 개념단단 수학 중1 | B8: 수학 | C8: 중1 | D8: 15500 | E8: 5390
A9: 개념단단 수학 중2 | B9: 수학 | C9: 중2 | D9: 17500 | E9: 5670 | F9: 2024-05
A10: 개념단단 수학 중3 | B10: 수학 | C10: 중3 | D10: 17000 | E10: 5720
A11: 개념단단 사회 중1 | B11: 사회 | C11: 중1 | D11: 17000 | E11: 5790
A12: 개념단단 사회 중2 | B12: 사회 | C12: 중2 | D12: 17000 | E12: 5400
A13: 개념단단 사회 중3 | B13: 사회 | C13: 중3 | D13: 17500 | E13: 5960
A14: 개념단단 과학 중1 | B14: 과학 | C14: 중1 | D14: 16000 | E14: 5660
A15: 개념단단 과학 중2 | B15: 과학 | C15: 중2 | D15: 17500 | E15: 5750
A16: 개념단단 과학 중3 | B16: 과학 | C16: 중3 | D16: 17000 | E16: 5990
A17: 완성노트 국어 중1 | B17: 국어 | C17: 중1 | D17: 17000 | E17: 5660
A18: 완성노트 국어 중2 | B18: 국어 | C18: 중2 | D18: 15500 | E18: 5470
A19: 완성노트 국어 중3 | B19: 국어 | C19: 중3 | D19: 18000 | E19: 6220
A20: 완성노트 수학 중1 | B20: 수학 | C20: 중1 | D20: 17000 | E20: 5650
A21: 완성노트 수학 중2 | B21: 수학 | C21: 중2 | D21: 17500 | E21: 5920
A22: 완성노트 수학 중3 | B22: 수학 | C22: 중3 | D22: 18500 | E22: 6360 | F22: 2024-12
A23: 완성노트 과학 중2 | B23: 과학 | C23: 중2 | D23: 16500 | E23: 5720
A24: 완성노트 과학 중3 | B24: 과학 | C24: 중3 | D24: 18000 | E24: 6350
A25: 완성노트 영어 중2 | B25: 영어 | C25: 중2 | D25: 17000 | E25: 5440
A26: 완성노트 영어 중3 | B26: 영어 | C26: 중3 | D26: 16500 | E26: 5290
A27: 한권끝 국어 초5 | B27: 국어 | C27: 초5 | D27: 13000 | E27: 4330 | F27: 2023-09
A28: 한권끝 국어 초6 | B28: 국어 | C28: 초6 | D28: 14000 | E28: 4690
A29: 한권끝 수학 초5 | B29: 수학 | C29: 초5 | D29: 15000 | E29: 4880
A30: 한권끝 수학 초6 | B30: 수학 | C30: 초6 | D30: 13000 | E30: 4170 | F30: 2024-09
A31: 한권끝 사회 초5 | B31: 사회 | C31: 초5 | D31: 13000 | E31: 4420
A32: 한권끝 사회 초6 | B32: 사회 | C32: 초6 | D32: 14000 | E32: 4460
A33: 한권끝 과학 초5 | B33: 과학 | C33: 초5 | D33: 14000 | E33: 4330
A34: 한권끝 과학 초6 | B34: 과학 | C34: 초6 | D34: 14000 | E34: 4360
A35: 한권끝 영어 초5 | B35: 영어 | C35: 초5 | D35: 14000 | E35: 4740
A36: 한권끝 영어 초6 | B36: 영어 | C36: 초6 | D36: 15000 | E36: 4870
A37: 첫걸음 영어 초5 | B37: 영어 | C37: 초5 | D37: 14500 | E37: 4540 | F37: 2026-03
A38: 첫걸음 영어 초6 | B38: 영어 | C38: 초6 | D38: 13500 | E38: 4380
A39: 첫걸음 영어 중1 | B39: 영어 | C39: 중1 | D39: 16000 | E39: 5110
A40: 첫걸음 수학 초5 | B40: 수학 | C40: 초5 | D40: 13500 | E40: 4150
...
